2025-01-11 09:07:11,022 - ERROR - ------------------------------------
Erro ao atualizar dados: HTTPSConnectionPool(host='api.binance.com', port=443): Read timed out. (read timeout=10)
Traceback (most recent call last):
  File "C:\Users\paulo\python\Robo crypto\.venv\Lib\site-packages\urllib3\connectionpool.py", line 534, in _make_request
    response = conn.getresponse()
  File "C:\Users\paulo\python\Robo crypto\.venv\Lib\site-packages\urllib3\connection.py", line 516, in getresponse
    httplib_response = super().getresponse()
  File "C:\Users\paulo\AppData\Local\Programs\Python\Python313\Lib\http\client.py", line 1428, in getresponse
    response.begin()
    ~~~~~~~~~~~~~~^^
  File "C:\Users\paulo\AppData\Local\Programs\Python\Python313\Lib\http\client.py", line 331, in begin
    version, status, reason = self._read_status()
                              ~~~~~~~~~~~~~~~~~^^
  File "C:\Users\paulo\AppData\Local\Programs\Python\Python313\Lib\http\client.py", line 292, in _read_status
    line = str(self.fp.readline(_MAXLINE + 1), "iso-8859-1")
               ~~~~~~~~~~~~~~~~^^^^^^^^^^^^^^
  File "C:\Users\paulo\AppData\Local\Programs\Python\Python313\Lib\socket.py", line 719, in readinto
    return self._sock.recv_into(b)
           ~~~~~~~~~~~~~~~~~~~~^^^
  File "C:\Users\paulo\AppData\Local\Programs\Python\Python313\Lib\ssl.py", line 1304, in recv_into
    return self.read(nbytes, buffer)
           ~~~~~~~~~^^^^^^^^^^^^^^^^
  File "C:\Users\paulo\AppData\Local\Programs\Python\Python313\Lib\ssl.py", line 1138, in read
    return self._sslobj.read(len, buffer)
           ~~~~~~~~~~~~~~~~~^^^^^^^^^^^^^
TimeoutError: The read operation timed out

The above exception was the direct cause of the following exception:

Traceback (most recent call last):
  File "C:\Users\paulo\python\Robo crypto\.venv\Lib\site-packages\requests\adapters.py", line 667, in send
    resp = conn.urlopen(
        method=request.method,
    ...<9 lines>...
        chunked=chunked,
    )
  File "C:\Users\paulo\python\Robo crypto\.venv\Lib\site-packages\urllib3\connectionpool.py", line 841, in urlopen
    retries = retries.increment(
        method, url, error=new_e, _pool=self, _stacktrace=sys.exc_info()[2]
    )
  File "C:\Users\paulo\python\Robo crypto\.venv\Lib\site-packages\urllib3\util\retry.py", line 474, in increment
    raise reraise(type(error), error, _stacktrace)
          ~~~~~~~^^^^^^^^^^^^^^^^^^^^^^^^^^^^^^^^^
  File "C:\Users\paulo\python\Robo crypto\.venv\Lib\site-packages\urllib3\util\util.py", line 39, in reraise
    raise value
  File "C:\Users\paulo\python\Robo crypto\.venv\Lib\site-packages\urllib3\connectionpool.py", line 787, in urlopen
    response = self._make_request(
        conn,
    ...<10 lines>...
        **response_kw,
    )
  File "C:\Users\paulo\python\Robo crypto\.venv\Lib\site-packages\urllib3\connectionpool.py", line 536, in _make_request
    self._raise_timeout(err=e, url=url, timeout_value=read_timeout)
    ~~~~~~~~~~~~~~~~~~~^^^^^^^^^^^^^^^^^^^^^^^^^^^^^^^^^^^^^^^^^^^^
  File "C:\Users\paulo\python\Robo crypto\.venv\Lib\site-packages\urllib3\connectionpool.py", line 367, in _raise_timeout
    raise ReadTimeoutError(
        self, url, f"Read timed out. (read timeout={timeout_value})"
    ) from err
urllib3.exceptions.ReadTimeoutError: HTTPSConnectionPool(host='api.binance.com', port=443): Read timed out. (read timeout=10)

During handling of the above exception, another exception occurred:

Traceback (most recent call last):
  File "c:\Users\paulo\python\Robo crypto\src\BinanceTrader2.py", line 64, in updateAllData
    self.account_data = self.getUpdatedAccountData()
                        ~~~~~~~~~~~~~~~~~~~~~~~~~~^^
  File "c:\Users\paulo\python\Robo crypto\src\BinanceTrader2.py", line 73, in getUpdatedAccountData
    return self.client_binance.get_account()
           ~~~~~~~~~~~~~~~~~~~~~~~~~~~~~~~^^
  File "C:\Users\paulo\python\Robo crypto\.venv\Lib\site-packages\binance\client.py", line 2036, in get_account
    return self._get("account", True, data=params)
           ~~~~~~~~~^^^^^^^^^^^^^^^^^^^^^^^^^^^^^^
  File "C:\Users\paulo\python\Robo crypto\.venv\Lib\site-packages\binance\client.py", line 176, in _get
    return self._request_api("get", path, signed, version, **kwargs)
           ~~~~~~~~~~~~~~~~~^^^^^^^^^^^^^^^^^^^^^^^^^^^^^^^^^^^^^^^^
  File "C:\Users\paulo\python\Robo crypto\.venv\Lib\site-packages\binance\client.py", line 113, in _request_api
    return self._request(method, uri, signed, **kwargs)
           ~~~~~~~~~~~~~^^^^^^^^^^^^^^^^^^^^^^^^^^^^^^^
  File "C:\Users\paulo\python\Robo crypto\.venv\Lib\site-packages\binance\client.py", line 88, in _request
    self.response = getattr(self.session, method)(uri, headers=headers, data=data, **kwargs)
                    ~~~~~~~~~~~~~~~~~~~~~~~~~~~~~^^^^^^^^^^^^^^^^^^^^^^^^^^^^^^^^^^^^^^^^^^^
  File "C:\Users\paulo\python\Robo crypto\.venv\Lib\site-packages\requests\sessions.py", line 602, in get
    return self.request("GET", url, **kwargs)
           ~~~~~~~~~~~~^^^^^^^^^^^^^^^^^^^^^^
  File "C:\Users\paulo\python\Robo crypto\.venv\Lib\site-packages\requests\sessions.py", line 589, in request
    resp = self.send(prep, **send_kwargs)
  File "C:\Users\paulo\python\Robo crypto\.venv\Lib\site-packages\requests\sessions.py", line 703, in send
    r = adapter.send(request, **kwargs)
  File "C:\Users\paulo\python\Robo crypto\.venv\Lib\site-packages\requests\adapters.py", line 713, in send
    raise ReadTimeout(e, request=request)
requests.exceptions.ReadTimeout: HTTPSConnectionPool(host='api.binance.com', port=443): Read timed out. (read timeout=10)
2025-01-11 09:07:11,142 - ERROR - ------------------------------------
Traceback (most recent call last):
  File "C:\Users\paulo\python\Robo crypto\.venv\Lib\site-packages\urllib3\connectionpool.py", line 534, in _make_request
    response = conn.getresponse()
  File "C:\Users\paulo\python\Robo crypto\.venv\Lib\site-packages\urllib3\connection.py", line 516, in getresponse
    httplib_response = super().getresponse()
  File "C:\Users\paulo\AppData\Local\Programs\Python\Python313\Lib\http\client.py", line 1428, in getresponse
    response.begin()
    ~~~~~~~~~~~~~~^^
  File "C:\Users\paulo\AppData\Local\Programs\Python\Python313\Lib\http\client.py", line 331, in begin
    version, status, reason = self._read_status()
                              ~~~~~~~~~~~~~~~~~^^
  File "C:\Users\paulo\AppData\Local\Programs\Python\Python313\Lib\http\client.py", line 292, in _read_status
    line = str(self.fp.readline(_MAXLINE + 1), "iso-8859-1")
               ~~~~~~~~~~~~~~~~^^^^^^^^^^^^^^
  File "C:\Users\paulo\AppData\Local\Programs\Python\Python313\Lib\socket.py", line 719, in readinto
    return self._sock.recv_into(b)
           ~~~~~~~~~~~~~~~~~~~~^^^
  File "C:\Users\paulo\AppData\Local\Programs\Python\Python313\Lib\ssl.py", line 1304, in recv_into
    return self.read(nbytes, buffer)
           ~~~~~~~~~^^^^^^^^^^^^^^^^
  File "C:\Users\paulo\AppData\Local\Programs\Python\Python313\Lib\ssl.py", line 1138, in read
    return self._sslobj.read(len, buffer)
           ~~~~~~~~~~~~~~~~~^^^^^^^^^^^^^
TimeoutError: The read operation timed out

The above exception was the direct cause of the following exception:

Traceback (most recent call last):
  File "C:\Users\paulo\python\Robo crypto\.venv\Lib\site-packages\requests\adapters.py", line 667, in send
    resp = conn.urlopen(
        method=request.method,
    ...<9 lines>...
        chunked=chunked,
    )
  File "C:\Users\paulo\python\Robo crypto\.venv\Lib\site-packages\urllib3\connectionpool.py", line 841, in urlopen
    retries = retries.increment(
        method, url, error=new_e, _pool=self, _stacktrace=sys.exc_info()[2]
    )
  File "C:\Users\paulo\python\Robo crypto\.venv\Lib\site-packages\urllib3\util\retry.py", line 474, in increment
    raise reraise(type(error), error, _stacktrace)
          ~~~~~~~^^^^^^^^^^^^^^^^^^^^^^^^^^^^^^^^^
  File "C:\Users\paulo\python\Robo crypto\.venv\Lib\site-packages\urllib3\util\util.py", line 39, in reraise
    raise value
  File "C:\Users\paulo\python\Robo crypto\.venv\Lib\site-packages\urllib3\connectionpool.py", line 787, in urlopen
    response = self._make_request(
        conn,
    ...<10 lines>...
        **response_kw,
    )
  File "C:\Users\paulo\python\Robo crypto\.venv\Lib\site-packages\urllib3\connectionpool.py", line 536, in _make_request
    self._raise_timeout(err=e, url=url, timeout_value=read_timeout)
    ~~~~~~~~~~~~~~~~~~~^^^^^^^^^^^^^^^^^^^^^^^^^^^^^^^^^^^^^^^^^^^^
  File "C:\Users\paulo\python\Robo crypto\.venv\Lib\site-packages\urllib3\connectionpool.py", line 367, in _raise_timeout
    raise ReadTimeoutError(
        self, url, f"Read timed out. (read timeout={timeout_value})"
    ) from err
urllib3.exceptions.ReadTimeoutError: HTTPSConnectionPool(host='api.binance.com', port=443): Read timed out. (read timeout=10)

During handling of the above exception, another exception occurred:

Traceback (most recent call last):
  File "c:\Users\paulo\python\Robo crypto\src\BinanceTrader2.py", line 64, in updateAllData
    self.account_data = self.getUpdatedAccountData()
                        ~~~~~~~~~~~~~~~~~~~~~~~~~~^^
  File "c:\Users\paulo\python\Robo crypto\src\BinanceTrader2.py", line 73, in getUpdatedAccountData
    return self.client_binance.get_account()
           ~~~~~~~~~~~~~~~~~~~~~~~~~~~~~~~^^
  File "C:\Users\paulo\python\Robo crypto\.venv\Lib\site-packages\binance\client.py", line 2036, in get_account
    return self._get("account", True, data=params)
           ~~~~~~~~~^^^^^^^^^^^^^^^^^^^^^^^^^^^^^^
  File "C:\Users\paulo\python\Robo crypto\.venv\Lib\site-packages\binance\client.py", line 176, in _get
    return self._request_api("get", path, signed, version, **kwargs)
           ~~~~~~~~~~~~~~~~~^^^^^^^^^^^^^^^^^^^^^^^^^^^^^^^^^^^^^^^^
  File "C:\Users\paulo\python\Robo crypto\.venv\Lib\site-packages\binance\client.py", line 113, in _request_api
    return self._request(method, uri, signed, **kwargs)
           ~~~~~~~~~~~~~^^^^^^^^^^^^^^^^^^^^^^^^^^^^^^^
  File "C:\Users\paulo\python\Robo crypto\.venv\Lib\site-packages\binance\client.py", line 88, in _request
    self.response = getattr(self.session, method)(uri, headers=headers, data=data, **kwargs)
                    ~~~~~~~~~~~~~~~~~~~~~~~~~~~~~^^^^^^^^^^^^^^^^^^^^^^^^^^^^^^^^^^^^^^^^^^^
  File "C:\Users\paulo\python\Robo crypto\.venv\Lib\site-packages\requests\sessions.py", line 602, in get
    return self.request("GET", url, **kwargs)
           ~~~~~~~~~~~~^^^^^^^^^^^^^^^^^^^^^^
  File "C:\Users\paulo\python\Robo crypto\.venv\Lib\site-packages\requests\sessions.py", line 589, in request
    resp = self.send(prep, **send_kwargs)
  File "C:\Users\paulo\python\Robo crypto\.venv\Lib\site-packages\requests\sessions.py", line 703, in send
    r = adapter.send(request, **kwargs)
  File "C:\Users\paulo\python\Robo crypto\.venv\Lib\site-packages\requests\adapters.py", line 713, in send
    raise ReadTimeout(e, request=request)
requests.exceptions.ReadTimeout: HTTPSConnectionPool(host='api.binance.com', port=443): Read timed out. (read timeout=10)
2025-01-11 09:08:11,171 - ERROR - ------------------------------------
Erro ao atualizar dados: HTTPSConnectionPool(host='api.binance.com', port=443): Max retries exceeded with url: /api/v3/account?recvWindow=10000&timestamp=1736597291150&signature=fdd7c4e38d35a4b62862c0bafb03590fec58ccddd8617ca027b5fc55c787ed9e (Caused by NameResolutionError("<urllib3.connection.HTTPSConnection object at 0x000001C3E9D14CD0>: Failed to resolve 'api.binance.com' ([Errno 11001] getaddrinfo failed)"))
Traceback (most recent call last):
  File "C:\Users\paulo\python\Robo crypto\.venv\Lib\site-packages\urllib3\connection.py", line 198, in _new_conn
    sock = connection.create_connection(
        (self._dns_host, self.port),
    ...<2 lines>...
        socket_options=self.socket_options,
    )
  File "C:\Users\paulo\python\Robo crypto\.venv\Lib\site-packages\urllib3\util\connection.py", line 60, in create_connection
    for res in socket.getaddrinfo(host, port, family, socket.SOCK_STREAM):
               ~~~~~~~~~~~~~~~~~~^^^^^^^^^^^^^^^^^^^^^^^^^^^^^^^^^^^^^^^^
  File "C:\Users\paulo\AppData\Local\Programs\Python\Python313\Lib\socket.py", line 975, in getaddrinfo
    for res in _socket.getaddrinfo(host, port, family, type, proto, flags):
               ~~~~~~~~~~~~~~~~~~~^^^^^^^^^^^^^^^^^^^^^^^^^^^^^^^^^^^^^^^^
socket.gaierror: [Errno 11001] getaddrinfo failed

The above exception was the direct cause of the following exception:

Traceback (most recent call last):
  File "C:\Users\paulo\python\Robo crypto\.venv\Lib\site-packages\urllib3\connectionpool.py", line 787, in urlopen
    response = self._make_request(
        conn,
    ...<10 lines>...
        **response_kw,
    )
  File "C:\Users\paulo\python\Robo crypto\.venv\Lib\site-packages\urllib3\connectionpool.py", line 488, in _make_request
    raise new_e
  File "C:\Users\paulo\python\Robo crypto\.venv\Lib\site-packages\urllib3\connectionpool.py", line 464, in _make_request
    self._validate_conn(conn)
    ~~~~~~~~~~~~~~~~~~~^^^^^^
  File "C:\Users\paulo\python\Robo crypto\.venv\Lib\site-packages\urllib3\connectionpool.py", line 1093, in _validate_conn
    conn.connect()
    ~~~~~~~~~~~~^^
  File "C:\Users\paulo\python\Robo crypto\.venv\Lib\site-packages\urllib3\connection.py", line 704, in connect
    self.sock = sock = self._new_conn()
                       ~~~~~~~~~~~~~~^^
  File "C:\Users\paulo\python\Robo crypto\.venv\Lib\site-packages\urllib3\connection.py", line 205, in _new_conn
    raise NameResolutionError(self.host, self, e) from e
urllib3.exceptions.NameResolutionError: <urllib3.connection.HTTPSConnection object at 0x000001C3E9D14CD0>: Failed to resolve 'api.binance.com' ([Errno 11001] getaddrinfo failed)

The above exception was the direct cause of the following exception:

Traceback (most recent call last):
  File "C:\Users\paulo\python\Robo crypto\.venv\Lib\site-packages\requests\adapters.py", line 667, in send
    resp = conn.urlopen(
        method=request.method,
    ...<9 lines>...
        chunked=chunked,
    )
  File "C:\Users\paulo\python\Robo crypto\.venv\Lib\site-packages\urllib3\connectionpool.py", line 841, in urlopen
    retries = retries.increment(
        method, url, error=new_e, _pool=self, _stacktrace=sys.exc_info()[2]
    )
  File "C:\Users\paulo\python\Robo crypto\.venv\Lib\site-packages\urllib3\util\retry.py", line 519, in increment
    raise MaxRetryError(_pool, url, reason) from reason  # type: ignore[arg-type]
    ^^^^^^^^^^^^^^^^^^^^^^^^^^^^^^^^^^^^^^^^^^^^^^^^^^^
urllib3.exceptions.MaxRetryError: HTTPSConnectionPool(host='api.binance.com', port=443): Max retries exceeded with url: /api/v3/account?recvWindow=10000&timestamp=1736597291150&signature=fdd7c4e38d35a4b62862c0bafb03590fec58ccddd8617ca027b5fc55c787ed9e (Caused by NameResolutionError("<urllib3.connection.HTTPSConnection object at 0x000001C3E9D14CD0>: Failed to resolve 'api.binance.com' ([Errno 11001] getaddrinfo failed)"))

During handling of the above exception, another exception occurred:

Traceback (most recent call last):
  File "c:\Users\paulo\python\Robo crypto\src\BinanceTrader2.py", line 64, in updateAllData
    self.account_data = self.getUpdatedAccountData()
                        ~~~~~~~~~~~~~~~~~~~~~~~~~~^^
  File "c:\Users\paulo\python\Robo crypto\src\BinanceTrader2.py", line 73, in getUpdatedAccountData
    return self.client_binance.get_account()
           ~~~~~~~~~~~~~~~~~~~~~~~~~~~~~~~^^
  File "C:\Users\paulo\python\Robo crypto\.venv\Lib\site-packages\binance\client.py", line 2036, in get_account
    return self._get("account", True, data=params)
           ~~~~~~~~~^^^^^^^^^^^^^^^^^^^^^^^^^^^^^^
  File "C:\Users\paulo\python\Robo crypto\.venv\Lib\site-packages\binance\client.py", line 176, in _get
    return self._request_api("get", path, signed, version, **kwargs)
           ~~~~~~~~~~~~~~~~~^^^^^^^^^^^^^^^^^^^^^^^^^^^^^^^^^^^^^^^^
  File "C:\Users\paulo\python\Robo crypto\.venv\Lib\site-packages\binance\client.py", line 113, in _request_api
    return self._request(method, uri, signed, **kwargs)
           ~~~~~~~~~~~~~^^^^^^^^^^^^^^^^^^^^^^^^^^^^^^^
  File "C:\Users\paulo\python\Robo crypto\.venv\Lib\site-packages\binance\client.py", line 88, in _request
    self.response = getattr(self.session, method)(uri, headers=headers, data=data, **kwargs)
                    ~~~~~~~~~~~~~~~~~~~~~~~~~~~~~^^^^^^^^^^^^^^^^^^^^^^^^^^^^^^^^^^^^^^^^^^^
  File "C:\Users\paulo\python\Robo crypto\.venv\Lib\site-packages\requests\sessions.py", line 602, in get
    return self.request("GET", url, **kwargs)
           ~~~~~~~~~~~~^^^^^^^^^^^^^^^^^^^^^^
  File "C:\Users\paulo\python\Robo crypto\.venv\Lib\site-packages\requests\sessions.py", line 589, in request
    resp = self.send(prep, **send_kwargs)
  File "C:\Users\paulo\python\Robo crypto\.venv\Lib\site-packages\requests\sessions.py", line 703, in send
    r = adapter.send(request, **kwargs)
  File "C:\Users\paulo\python\Robo crypto\.venv\Lib\site-packages\requests\adapters.py", line 700, in send
    raise ConnectionError(e, request=request)
requests.exceptions.ConnectionError: HTTPSConnectionPool(host='api.binance.com', port=443): Max retries exceeded with url: /api/v3/account?recvWindow=10000&timestamp=1736597291150&signature=fdd7c4e38d35a4b62862c0bafb03590fec58ccddd8617ca027b5fc55c787ed9e (Caused by NameResolutionError("<urllib3.connection.HTTPSConnection object at 0x000001C3E9D14CD0>: Failed to resolve 'api.binance.com' ([Errno 11001] getaddrinfo failed)"))
2025-01-11 09:08:11,198 - ERROR - ------------------------------------
Traceback (most recent call last):
  File "C:\Users\paulo\python\Robo crypto\.venv\Lib\site-packages\urllib3\connection.py", line 198, in _new_conn
    sock = connection.create_connection(
        (self._dns_host, self.port),
    ...<2 lines>...
        socket_options=self.socket_options,
    )
  File "C:\Users\paulo\python\Robo crypto\.venv\Lib\site-packages\urllib3\util\connection.py", line 60, in create_connection
    for res in socket.getaddrinfo(host, port, family, socket.SOCK_STREAM):
               ~~~~~~~~~~~~~~~~~~^^^^^^^^^^^^^^^^^^^^^^^^^^^^^^^^^^^^^^^^
  File "C:\Users\paulo\AppData\Local\Programs\Python\Python313\Lib\socket.py", line 975, in getaddrinfo
    for res in _socket.getaddrinfo(host, port, family, type, proto, flags):
               ~~~~~~~~~~~~~~~~~~~^^^^^^^^^^^^^^^^^^^^^^^^^^^^^^^^^^^^^^^^
socket.gaierror: [Errno 11001] getaddrinfo failed

The above exception was the direct cause of the following exception:

Traceback (most recent call last):
  File "C:\Users\paulo\python\Robo crypto\.venv\Lib\site-packages\urllib3\connectionpool.py", line 787, in urlopen
    response = self._make_request(
        conn,
    ...<10 lines>...
        **response_kw,
    )
  File "C:\Users\paulo\python\Robo crypto\.venv\Lib\site-packages\urllib3\connectionpool.py", line 488, in _make_request
    raise new_e
  File "C:\Users\paulo\python\Robo crypto\.venv\Lib\site-packages\urllib3\connectionpool.py", line 464, in _make_request
    self._validate_conn(conn)
    ~~~~~~~~~~~~~~~~~~~^^^^^^
  File "C:\Users\paulo\python\Robo crypto\.venv\Lib\site-packages\urllib3\connectionpool.py", line 1093, in _validate_conn
    conn.connect()
    ~~~~~~~~~~~~^^
  File "C:\Users\paulo\python\Robo crypto\.venv\Lib\site-packages\urllib3\connection.py", line 704, in connect
    self.sock = sock = self._new_conn()
                       ~~~~~~~~~~~~~~^^
  File "C:\Users\paulo\python\Robo crypto\.venv\Lib\site-packages\urllib3\connection.py", line 205, in _new_conn
    raise NameResolutionError(self.host, self, e) from e
urllib3.exceptions.NameResolutionError: <urllib3.connection.HTTPSConnection object at 0x000001C3E9D14CD0>: Failed to resolve 'api.binance.com' ([Errno 11001] getaddrinfo failed)

The above exception was the direct cause of the following exception:

Traceback (most recent call last):
  File "C:\Users\paulo\python\Robo crypto\.venv\Lib\site-packages\requests\adapters.py", line 667, in send
    resp = conn.urlopen(
        method=request.method,
    ...<9 lines>...
        chunked=chunked,
    )
  File "C:\Users\paulo\python\Robo crypto\.venv\Lib\site-packages\urllib3\connectionpool.py", line 841, in urlopen
    retries = retries.increment(
        method, url, error=new_e, _pool=self, _stacktrace=sys.exc_info()[2]
    )
  File "C:\Users\paulo\python\Robo crypto\.venv\Lib\site-packages\urllib3\util\retry.py", line 519, in increment
    raise MaxRetryError(_pool, url, reason) from reason  # type: ignore[arg-type]
    ^^^^^^^^^^^^^^^^^^^^^^^^^^^^^^^^^^^^^^^^^^^^^^^^^^^
urllib3.exceptions.MaxRetryError: HTTPSConnectionPool(host='api.binance.com', port=443): Max retries exceeded with url: /api/v3/account?recvWindow=10000&timestamp=1736597291150&signature=fdd7c4e38d35a4b62862c0bafb03590fec58ccddd8617ca027b5fc55c787ed9e (Caused by NameResolutionError("<urllib3.connection.HTTPSConnection object at 0x000001C3E9D14CD0>: Failed to resolve 'api.binance.com' ([Errno 11001] getaddrinfo failed)"))

During handling of the above exception, another exception occurred:

Traceback (most recent call last):
  File "c:\Users\paulo\python\Robo crypto\src\BinanceTrader2.py", line 64, in updateAllData
    self.account_data = self.getUpdatedAccountData()
                        ~~~~~~~~~~~~~~~~~~~~~~~~~~^^
  File "c:\Users\paulo\python\Robo crypto\src\BinanceTrader2.py", line 73, in getUpdatedAccountData
    return self.client_binance.get_account()
           ~~~~~~~~~~~~~~~~~~~~~~~~~~~~~~~^^
  File "C:\Users\paulo\python\Robo crypto\.venv\Lib\site-packages\binance\client.py", line 2036, in get_account
    return self._get("account", True, data=params)
           ~~~~~~~~~^^^^^^^^^^^^^^^^^^^^^^^^^^^^^^
  File "C:\Users\paulo\python\Robo crypto\.venv\Lib\site-packages\binance\client.py", line 176, in _get
    return self._request_api("get", path, signed, version, **kwargs)
           ~~~~~~~~~~~~~~~~~^^^^^^^^^^^^^^^^^^^^^^^^^^^^^^^^^^^^^^^^
  File "C:\Users\paulo\python\Robo crypto\.venv\Lib\site-packages\binance\client.py", line 113, in _request_api
    return self._request(method, uri, signed, **kwargs)
           ~~~~~~~~~~~~~^^^^^^^^^^^^^^^^^^^^^^^^^^^^^^^
  File "C:\Users\paulo\python\Robo crypto\.venv\Lib\site-packages\binance\client.py", line 88, in _request
    self.response = getattr(self.session, method)(uri, headers=headers, data=data, **kwargs)
                    ~~~~~~~~~~~~~~~~~~~~~~~~~~~~~^^^^^^^^^^^^^^^^^^^^^^^^^^^^^^^^^^^^^^^^^^^
  File "C:\Users\paulo\python\Robo crypto\.venv\Lib\site-packages\requests\sessions.py", line 602, in get
    return self.request("GET", url, **kwargs)
           ~~~~~~~~~~~~^^^^^^^^^^^^^^^^^^^^^^
  File "C:\Users\paulo\python\Robo crypto\.venv\Lib\site-packages\requests\sessions.py", line 589, in request
    resp = self.send(prep, **send_kwargs)
  File "C:\Users\paulo\python\Robo crypto\.venv\Lib\site-packages\requests\sessions.py", line 703, in send
    r = adapter.send(request, **kwargs)
  File "C:\Users\paulo\python\Robo crypto\.venv\Lib\site-packages\requests\adapters.py", line 700, in send
    raise ConnectionError(e, request=request)
requests.exceptions.ConnectionError: HTTPSConnectionPool(host='api.binance.com', port=443): Max retries exceeded with url: /api/v3/account?recvWindow=10000&timestamp=1736597291150&signature=fdd7c4e38d35a4b62862c0bafb03590fec58ccddd8617ca027b5fc55c787ed9e (Caused by NameResolutionError("<urllib3.connection.HTTPSConnection object at 0x000001C3E9D14CD0>: Failed to resolve 'api.binance.com' ([Errno 11001] getaddrinfo failed)"))
2025-01-11 10:37:01,888 - ERROR - Erro da Binance API: APIError(code=-1013): Filter failure: NOTIONAL
Traceback (most recent call last):
  File "c:\Users\paulo\python\Robo crypto\src\BinanceTrader2.py", line 162, in execute_trade
    order = self.client_binance.create_order(
        symbol=self.operation_code,
    ...<2 lines>...
        quantity=str(quantity)
    )
  File "C:\Users\paulo\python\Robo crypto\.venv\Lib\site-packages\binance\client.py", line 1333, in create_order
    return self._post("order", True, data=params)
           ~~~~~~~~~~^^^^^^^^^^^^^^^^^^^^^^^^^^^^
  File "C:\Users\paulo\python\Robo crypto\.venv\Lib\site-packages\binance\client.py", line 181, in _post
    return self._request_api("post", path, signed, version, **kwargs)
           ~~~~~~~~~~~~~~~~~^^^^^^^^^^^^^^^^^^^^^^^^^^^^^^^^^^^^^^^^^
  File "C:\Users\paulo\python\Robo crypto\.venv\Lib\site-packages\binance\client.py", line 113, in _request_api
    return self._request(method, uri, signed, **kwargs)
           ~~~~~~~~~~~~~^^^^^^^^^^^^^^^^^^^^^^^^^^^^^^^
  File "C:\Users\paulo\python\Robo crypto\.venv\Lib\site-packages\binance\client.py", line 89, in _request
    return self._handle_response(self.response)
           ~~~~~~~~~~~~~~~~~~~~~^^^^^^^^^^^^^^^
  File "C:\Users\paulo\python\Robo crypto\.venv\Lib\site-packages\binance\client.py", line 98, in _handle_response
    raise BinanceAPIException(response, response.status_code, response.text)
binance.exceptions.BinanceAPIException: APIError(code=-1013): Filter failure: NOTIONAL
2025-01-11 10:38:04,044 - ERROR - Erro da Binance API: APIError(code=-1013): Filter failure: NOTIONAL
Traceback (most recent call last):
  File "c:\Users\paulo\python\Robo crypto\src\BinanceTrader2.py", line 162, in execute_trade
    order = self.client_binance.create_order(
        symbol=self.operation_code,
    ...<2 lines>...
        quantity=str(quantity)
    )
  File "C:\Users\paulo\python\Robo crypto\.venv\Lib\site-packages\binance\client.py", line 1333, in create_order
    return self._post("order", True, data=params)
           ~~~~~~~~~~^^^^^^^^^^^^^^^^^^^^^^^^^^^^
  File "C:\Users\paulo\python\Robo crypto\.venv\Lib\site-packages\binance\client.py", line 181, in _post
    return self._request_api("post", path, signed, version, **kwargs)
           ~~~~~~~~~~~~~~~~~^^^^^^^^^^^^^^^^^^^^^^^^^^^^^^^^^^^^^^^^^
  File "C:\Users\paulo\python\Robo crypto\.venv\Lib\site-packages\binance\client.py", line 113, in _request_api
    return self._request(method, uri, signed, **kwargs)
           ~~~~~~~~~~~~~^^^^^^^^^^^^^^^^^^^^^^^^^^^^^^^
  File "C:\Users\paulo\python\Robo crypto\.venv\Lib\site-packages\binance\client.py", line 89, in _request
    return self._handle_response(self.response)
           ~~~~~~~~~~~~~~~~~~~~~^^^^^^^^^^^^^^^
  File "C:\Users\paulo\python\Robo crypto\.venv\Lib\site-packages\binance\client.py", line 98, in _handle_response
    raise BinanceAPIException(response, response.status_code, response.text)
binance.exceptions.BinanceAPIException: APIError(code=-1013): Filter failure: NOTIONAL
2025-01-11 10:39:06,304 - ERROR - Erro da Binance API: APIError(code=-1013): Filter failure: NOTIONAL
Traceback (most recent call last):
  File "c:\Users\paulo\python\Robo crypto\src\BinanceTrader2.py", line 162, in execute_trade
    order = self.client_binance.create_order(
        symbol=self.operation_code,
    ...<2 lines>...
        quantity=str(quantity)
    )
  File "C:\Users\paulo\python\Robo crypto\.venv\Lib\site-packages\binance\client.py", line 1333, in create_order
    return self._post("order", True, data=params)
           ~~~~~~~~~~^^^^^^^^^^^^^^^^^^^^^^^^^^^^
  File "C:\Users\paulo\python\Robo crypto\.venv\Lib\site-packages\binance\client.py", line 181, in _post
    return self._request_api("post", path, signed, version, **kwargs)
           ~~~~~~~~~~~~~~~~~^^^^^^^^^^^^^^^^^^^^^^^^^^^^^^^^^^^^^^^^^
  File "C:\Users\paulo\python\Robo crypto\.venv\Lib\site-packages\binance\client.py", line 113, in _request_api
    return self._request(method, uri, signed, **kwargs)
           ~~~~~~~~~~~~~^^^^^^^^^^^^^^^^^^^^^^^^^^^^^^^
  File "C:\Users\paulo\python\Robo crypto\.venv\Lib\site-packages\binance\client.py", line 89, in _request
    return self._handle_response(self.response)
           ~~~~~~~~~~~~~~~~~~~~~^^^^^^^^^^^^^^^
  File "C:\Users\paulo\python\Robo crypto\.venv\Lib\site-packages\binance\client.py", line 98, in _handle_response
    raise BinanceAPIException(response, response.status_code, response.text)
binance.exceptions.BinanceAPIException: APIError(code=-1013): Filter failure: NOTIONAL
2025-01-11 10:40:08,573 - ERROR - Erro da Binance API: APIError(code=-1013): Filter failure: NOTIONAL
Traceback (most recent call last):
  File "c:\Users\paulo\python\Robo crypto\src\BinanceTrader2.py", line 162, in execute_trade
    order = self.client_binance.create_order(
        symbol=self.operation_code,
    ...<2 lines>...
        quantity=str(quantity)
    )
  File "C:\Users\paulo\python\Robo crypto\.venv\Lib\site-packages\binance\client.py", line 1333, in create_order
    return self._post("order", True, data=params)
           ~~~~~~~~~~^^^^^^^^^^^^^^^^^^^^^^^^^^^^
  File "C:\Users\paulo\python\Robo crypto\.venv\Lib\site-packages\binance\client.py", line 181, in _post
    return self._request_api("post", path, signed, version, **kwargs)
           ~~~~~~~~~~~~~~~~~^^^^^^^^^^^^^^^^^^^^^^^^^^^^^^^^^^^^^^^^^
  File "C:\Users\paulo\python\Robo crypto\.venv\Lib\site-packages\binance\client.py", line 113, in _request_api
    return self._request(method, uri, signed, **kwargs)
           ~~~~~~~~~~~~~^^^^^^^^^^^^^^^^^^^^^^^^^^^^^^^
  File "C:\Users\paulo\python\Robo crypto\.venv\Lib\site-packages\binance\client.py", line 89, in _request
    return self._handle_response(self.response)
           ~~~~~~~~~~~~~~~~~~~~~^^^^^^^^^^^^^^^
  File "C:\Users\paulo\python\Robo crypto\.venv\Lib\site-packages\binance\client.py", line 98, in _handle_response
    raise BinanceAPIException(response, response.status_code, response.text)
binance.exceptions.BinanceAPIException: APIError(code=-1013): Filter failure: NOTIONAL
2025-01-11 10:41:10,221 - ERROR - Erro da Binance API: APIError(code=-1013): Filter failure: NOTIONAL
Traceback (most recent call last):
  File "c:\Users\paulo\python\Robo crypto\src\BinanceTrader2.py", line 162, in execute_trade
    order = self.client_binance.create_order(
        symbol=self.operation_code,
    ...<2 lines>...
        quantity=str(quantity)
    )
  File "C:\Users\paulo\python\Robo crypto\.venv\Lib\site-packages\binance\client.py", line 1333, in create_order
    return self._post("order", True, data=params)
           ~~~~~~~~~~^^^^^^^^^^^^^^^^^^^^^^^^^^^^
  File "C:\Users\paulo\python\Robo crypto\.venv\Lib\site-packages\binance\client.py", line 181, in _post
    return self._request_api("post", path, signed, version, **kwargs)
           ~~~~~~~~~~~~~~~~~^^^^^^^^^^^^^^^^^^^^^^^^^^^^^^^^^^^^^^^^^
  File "C:\Users\paulo\python\Robo crypto\.venv\Lib\site-packages\binance\client.py", line 113, in _request_api
    return self._request(method, uri, signed, **kwargs)
           ~~~~~~~~~~~~~^^^^^^^^^^^^^^^^^^^^^^^^^^^^^^^
  File "C:\Users\paulo\python\Robo crypto\.venv\Lib\site-packages\binance\client.py", line 89, in _request
    return self._handle_response(self.response)
           ~~~~~~~~~~~~~~~~~~~~~^^^^^^^^^^^^^^^
  File "C:\Users\paulo\python\Robo crypto\.venv\Lib\site-packages\binance\client.py", line 98, in _handle_response
    raise BinanceAPIException(response, response.status_code, response.text)
binance.exceptions.BinanceAPIException: APIError(code=-1013): Filter failure: NOTIONAL
2025-01-11 10:42:12,268 - ERROR - Erro da Binance API: APIError(code=-1013): Filter failure: NOTIONAL
Traceback (most recent call last):
  File "c:\Users\paulo\python\Robo crypto\src\BinanceTrader2.py", line 162, in execute_trade
    order = self.client_binance.create_order(
        symbol=self.operation_code,
    ...<2 lines>...
        quantity=str(quantity)
    )
  File "C:\Users\paulo\python\Robo crypto\.venv\Lib\site-packages\binance\client.py", line 1333, in create_order
    return self._post("order", True, data=params)
           ~~~~~~~~~~^^^^^^^^^^^^^^^^^^^^^^^^^^^^
  File "C:\Users\paulo\python\Robo crypto\.venv\Lib\site-packages\binance\client.py", line 181, in _post
    return self._request_api("post", path, signed, version, **kwargs)
           ~~~~~~~~~~~~~~~~~^^^^^^^^^^^^^^^^^^^^^^^^^^^^^^^^^^^^^^^^^
  File "C:\Users\paulo\python\Robo crypto\.venv\Lib\site-packages\binance\client.py", line 113, in _request_api
    return self._request(method, uri, signed, **kwargs)
           ~~~~~~~~~~~~~^^^^^^^^^^^^^^^^^^^^^^^^^^^^^^^
  File "C:\Users\paulo\python\Robo crypto\.venv\Lib\site-packages\binance\client.py", line 89, in _request
    return self._handle_response(self.response)
           ~~~~~~~~~~~~~~~~~~~~~^^^^^^^^^^^^^^^
  File "C:\Users\paulo\python\Robo crypto\.venv\Lib\site-packages\binance\client.py", line 98, in _handle_response
    raise BinanceAPIException(response, response.status_code, response.text)
binance.exceptions.BinanceAPIException: APIError(code=-1013): Filter failure: NOTIONAL
2025-01-11 10:43:14,628 - ERROR - Erro da Binance API: APIError(code=-1013): Filter failure: NOTIONAL
Traceback (most recent call last):
  File "c:\Users\paulo\python\Robo crypto\src\BinanceTrader2.py", line 162, in execute_trade
    order = self.client_binance.create_order(
        symbol=self.operation_code,
    ...<2 lines>...
        quantity=str(quantity)
    )
  File "C:\Users\paulo\python\Robo crypto\.venv\Lib\site-packages\binance\client.py", line 1333, in create_order
    return self._post("order", True, data=params)
           ~~~~~~~~~~^^^^^^^^^^^^^^^^^^^^^^^^^^^^
  File "C:\Users\paulo\python\Robo crypto\.venv\Lib\site-packages\binance\client.py", line 181, in _post
    return self._request_api("post", path, signed, version, **kwargs)
           ~~~~~~~~~~~~~~~~~^^^^^^^^^^^^^^^^^^^^^^^^^^^^^^^^^^^^^^^^^
  File "C:\Users\paulo\python\Robo crypto\.venv\Lib\site-packages\binance\client.py", line 113, in _request_api
    return self._request(method, uri, signed, **kwargs)
           ~~~~~~~~~~~~~^^^^^^^^^^^^^^^^^^^^^^^^^^^^^^^
  File "C:\Users\paulo\python\Robo crypto\.venv\Lib\site-packages\binance\client.py", line 89, in _request
    return self._handle_response(self.response)
           ~~~~~~~~~~~~~~~~~~~~~^^^^^^^^^^^^^^^
  File "C:\Users\paulo\python\Robo crypto\.venv\Lib\site-packages\binance\client.py", line 98, in _handle_response
    raise BinanceAPIException(response, response.status_code, response.text)
binance.exceptions.BinanceAPIException: APIError(code=-1013): Filter failure: NOTIONAL
2025-01-11 10:44:16,480 - ERROR - Erro da Binance API: APIError(code=-1013): Filter failure: NOTIONAL
Traceback (most recent call last):
  File "c:\Users\paulo\python\Robo crypto\src\BinanceTrader2.py", line 162, in execute_trade
    order = self.client_binance.create_order(
        symbol=self.operation_code,
    ...<2 lines>...
        quantity=str(quantity)
    )
  File "C:\Users\paulo\python\Robo crypto\.venv\Lib\site-packages\binance\client.py", line 1333, in create_order
    return self._post("order", True, data=params)
           ~~~~~~~~~~^^^^^^^^^^^^^^^^^^^^^^^^^^^^
  File "C:\Users\paulo\python\Robo crypto\.venv\Lib\site-packages\binance\client.py", line 181, in _post
    return self._request_api("post", path, signed, version, **kwargs)
           ~~~~~~~~~~~~~~~~~^^^^^^^^^^^^^^^^^^^^^^^^^^^^^^^^^^^^^^^^^
  File "C:\Users\paulo\python\Robo crypto\.venv\Lib\site-packages\binance\client.py", line 113, in _request_api
    return self._request(method, uri, signed, **kwargs)
           ~~~~~~~~~~~~~^^^^^^^^^^^^^^^^^^^^^^^^^^^^^^^
  File "C:\Users\paulo\python\Robo crypto\.venv\Lib\site-packages\binance\client.py", line 89, in _request
    return self._handle_response(self.response)
           ~~~~~~~~~~~~~~~~~~~~~^^^^^^^^^^^^^^^
  File "C:\Users\paulo\python\Robo crypto\.venv\Lib\site-packages\binance\client.py", line 98, in _handle_response
    raise BinanceAPIException(response, response.status_code, response.text)
binance.exceptions.BinanceAPIException: APIError(code=-1013): Filter failure: NOTIONAL
2025-01-11 10:45:18,343 - ERROR - Erro da Binance API: APIError(code=-1013): Filter failure: NOTIONAL
Traceback (most recent call last):
  File "c:\Users\paulo\python\Robo crypto\src\BinanceTrader2.py", line 162, in execute_trade
    order = self.client_binance.create_order(
        symbol=self.operation_code,
    ...<2 lines>...
        quantity=str(quantity)
    )
  File "C:\Users\paulo\python\Robo crypto\.venv\Lib\site-packages\binance\client.py", line 1333, in create_order
    return self._post("order", True, data=params)
           ~~~~~~~~~~^^^^^^^^^^^^^^^^^^^^^^^^^^^^
  File "C:\Users\paulo\python\Robo crypto\.venv\Lib\site-packages\binance\client.py", line 181, in _post
    return self._request_api("post", path, signed, version, **kwargs)
           ~~~~~~~~~~~~~~~~~^^^^^^^^^^^^^^^^^^^^^^^^^^^^^^^^^^^^^^^^^
  File "C:\Users\paulo\python\Robo crypto\.venv\Lib\site-packages\binance\client.py", line 113, in _request_api
    return self._request(method, uri, signed, **kwargs)
           ~~~~~~~~~~~~~^^^^^^^^^^^^^^^^^^^^^^^^^^^^^^^
  File "C:\Users\paulo\python\Robo crypto\.venv\Lib\site-packages\binance\client.py", line 89, in _request
    return self._handle_response(self.response)
           ~~~~~~~~~~~~~~~~~~~~~^^^^^^^^^^^^^^^
  File "C:\Users\paulo\python\Robo crypto\.venv\Lib\site-packages\binance\client.py", line 98, in _handle_response
    raise BinanceAPIException(response, response.status_code, response.text)
binance.exceptions.BinanceAPIException: APIError(code=-1013): Filter failure: NOTIONAL
2025-01-11 10:46:20,488 - ERROR - Erro da Binance API: APIError(code=-1013): Filter failure: NOTIONAL
Traceback (most recent call last):
  File "c:\Users\paulo\python\Robo crypto\src\BinanceTrader2.py", line 162, in execute_trade
    order = self.client_binance.create_order(
        symbol=self.operation_code,
    ...<2 lines>...
        quantity=str(quantity)
    )
  File "C:\Users\paulo\python\Robo crypto\.venv\Lib\site-packages\binance\client.py", line 1333, in create_order
    return self._post("order", True, data=params)
           ~~~~~~~~~~^^^^^^^^^^^^^^^^^^^^^^^^^^^^
  File "C:\Users\paulo\python\Robo crypto\.venv\Lib\site-packages\binance\client.py", line 181, in _post
    return self._request_api("post", path, signed, version, **kwargs)
           ~~~~~~~~~~~~~~~~~^^^^^^^^^^^^^^^^^^^^^^^^^^^^^^^^^^^^^^^^^
  File "C:\Users\paulo\python\Robo crypto\.venv\Lib\site-packages\binance\client.py", line 113, in _request_api
    return self._request(method, uri, signed, **kwargs)
           ~~~~~~~~~~~~~^^^^^^^^^^^^^^^^^^^^^^^^^^^^^^^
  File "C:\Users\paulo\python\Robo crypto\.venv\Lib\site-packages\binance\client.py", line 89, in _request
    return self._handle_response(self.response)
           ~~~~~~~~~~~~~~~~~~~~~^^^^^^^^^^^^^^^
  File "C:\Users\paulo\python\Robo crypto\.venv\Lib\site-packages\binance\client.py", line 98, in _handle_response
    raise BinanceAPIException(response, response.status_code, response.text)
binance.exceptions.BinanceAPIException: APIError(code=-1013): Filter failure: NOTIONAL
2025-01-11 10:47:22,338 - ERROR - Erro da Binance API: APIError(code=-1013): Filter failure: NOTIONAL
Traceback (most recent call last):
  File "c:\Users\paulo\python\Robo crypto\src\BinanceTrader2.py", line 162, in execute_trade
    order = self.client_binance.create_order(
        symbol=self.operation_code,
    ...<2 lines>...
        quantity=str(quantity)
    )
  File "C:\Users\paulo\python\Robo crypto\.venv\Lib\site-packages\binance\client.py", line 1333, in create_order
    return self._post("order", True, data=params)
           ~~~~~~~~~~^^^^^^^^^^^^^^^^^^^^^^^^^^^^
  File "C:\Users\paulo\python\Robo crypto\.venv\Lib\site-packages\binance\client.py", line 181, in _post
    return self._request_api("post", path, signed, version, **kwargs)
           ~~~~~~~~~~~~~~~~~^^^^^^^^^^^^^^^^^^^^^^^^^^^^^^^^^^^^^^^^^
  File "C:\Users\paulo\python\Robo crypto\.venv\Lib\site-packages\binance\client.py", line 113, in _request_api
    return self._request(method, uri, signed, **kwargs)
           ~~~~~~~~~~~~~^^^^^^^^^^^^^^^^^^^^^^^^^^^^^^^
  File "C:\Users\paulo\python\Robo crypto\.venv\Lib\site-packages\binance\client.py", line 89, in _request
    return self._handle_response(self.response)
           ~~~~~~~~~~~~~~~~~~~~~^^^^^^^^^^^^^^^
  File "C:\Users\paulo\python\Robo crypto\.venv\Lib\site-packages\binance\client.py", line 98, in _handle_response
    raise BinanceAPIException(response, response.status_code, response.text)
binance.exceptions.BinanceAPIException: APIError(code=-1013): Filter failure: NOTIONAL
2025-01-11 10:48:24,084 - ERROR - Erro da Binance API: APIError(code=-1013): Filter failure: NOTIONAL
Traceback (most recent call last):
  File "c:\Users\paulo\python\Robo crypto\src\BinanceTrader2.py", line 162, in execute_trade
    order = self.client_binance.create_order(
        symbol=self.operation_code,
    ...<2 lines>...
        quantity=str(quantity)
    )
  File "C:\Users\paulo\python\Robo crypto\.venv\Lib\site-packages\binance\client.py", line 1333, in create_order
    return self._post("order", True, data=params)
           ~~~~~~~~~~^^^^^^^^^^^^^^^^^^^^^^^^^^^^
  File "C:\Users\paulo\python\Robo crypto\.venv\Lib\site-packages\binance\client.py", line 181, in _post
    return self._request_api("post", path, signed, version, **kwargs)
           ~~~~~~~~~~~~~~~~~^^^^^^^^^^^^^^^^^^^^^^^^^^^^^^^^^^^^^^^^^
  File "C:\Users\paulo\python\Robo crypto\.venv\Lib\site-packages\binance\client.py", line 113, in _request_api
    return self._request(method, uri, signed, **kwargs)
           ~~~~~~~~~~~~~^^^^^^^^^^^^^^^^^^^^^^^^^^^^^^^
  File "C:\Users\paulo\python\Robo crypto\.venv\Lib\site-packages\binance\client.py", line 89, in _request
    return self._handle_response(self.response)
           ~~~~~~~~~~~~~~~~~~~~~^^^^^^^^^^^^^^^
  File "C:\Users\paulo\python\Robo crypto\.venv\Lib\site-packages\binance\client.py", line 98, in _handle_response
    raise BinanceAPIException(response, response.status_code, response.text)
binance.exceptions.BinanceAPIException: APIError(code=-1013): Filter failure: NOTIONAL
2025-01-11 10:49:25,938 - ERROR - Erro da Binance API: APIError(code=-1013): Filter failure: NOTIONAL
Traceback (most recent call last):
  File "c:\Users\paulo\python\Robo crypto\src\BinanceTrader2.py", line 162, in execute_trade
    order = self.client_binance.create_order(
        symbol=self.operation_code,
    ...<2 lines>...
        quantity=str(quantity)
    )
  File "C:\Users\paulo\python\Robo crypto\.venv\Lib\site-packages\binance\client.py", line 1333, in create_order
    return self._post("order", True, data=params)
           ~~~~~~~~~~^^^^^^^^^^^^^^^^^^^^^^^^^^^^
  File "C:\Users\paulo\python\Robo crypto\.venv\Lib\site-packages\binance\client.py", line 181, in _post
    return self._request_api("post", path, signed, version, **kwargs)
           ~~~~~~~~~~~~~~~~~^^^^^^^^^^^^^^^^^^^^^^^^^^^^^^^^^^^^^^^^^
  File "C:\Users\paulo\python\Robo crypto\.venv\Lib\site-packages\binance\client.py", line 113, in _request_api
    return self._request(method, uri, signed, **kwargs)
           ~~~~~~~~~~~~~^^^^^^^^^^^^^^^^^^^^^^^^^^^^^^^
  File "C:\Users\paulo\python\Robo crypto\.venv\Lib\site-packages\binance\client.py", line 89, in _request
    return self._handle_response(self.response)
           ~~~~~~~~~~~~~~~~~~~~~^^^^^^^^^^^^^^^
  File "C:\Users\paulo\python\Robo crypto\.venv\Lib\site-packages\binance\client.py", line 98, in _handle_response
    raise BinanceAPIException(response, response.status_code, response.text)
binance.exceptions.BinanceAPIException: APIError(code=-1013): Filter failure: NOTIONAL
2025-01-11 10:50:27,991 - ERROR - Erro da Binance API: APIError(code=-1013): Filter failure: NOTIONAL
Traceback (most recent call last):
  File "c:\Users\paulo\python\Robo crypto\src\BinanceTrader2.py", line 162, in execute_trade
    order = self.client_binance.create_order(
        symbol=self.operation_code,
    ...<2 lines>...
        quantity=str(quantity)
    )
  File "C:\Users\paulo\python\Robo crypto\.venv\Lib\site-packages\binance\client.py", line 1333, in create_order
    return self._post("order", True, data=params)
           ~~~~~~~~~~^^^^^^^^^^^^^^^^^^^^^^^^^^^^
  File "C:\Users\paulo\python\Robo crypto\.venv\Lib\site-packages\binance\client.py", line 181, in _post
    return self._request_api("post", path, signed, version, **kwargs)
           ~~~~~~~~~~~~~~~~~^^^^^^^^^^^^^^^^^^^^^^^^^^^^^^^^^^^^^^^^^
  File "C:\Users\paulo\python\Robo crypto\.venv\Lib\site-packages\binance\client.py", line 113, in _request_api
    return self._request(method, uri, signed, **kwargs)
           ~~~~~~~~~~~~~^^^^^^^^^^^^^^^^^^^^^^^^^^^^^^^
  File "C:\Users\paulo\python\Robo crypto\.venv\Lib\site-packages\binance\client.py", line 89, in _request
    return self._handle_response(self.response)
           ~~~~~~~~~~~~~~~~~~~~~^^^^^^^^^^^^^^^
  File "C:\Users\paulo\python\Robo crypto\.venv\Lib\site-packages\binance\client.py", line 98, in _handle_response
    raise BinanceAPIException(response, response.status_code, response.text)
binance.exceptions.BinanceAPIException: APIError(code=-1013): Filter failure: NOTIONAL
2025-01-11 10:51:29,714 - ERROR - Erro da Binance API: APIError(code=-1013): Filter failure: NOTIONAL
Traceback (most recent call last):
  File "c:\Users\paulo\python\Robo crypto\src\BinanceTrader2.py", line 162, in execute_trade
    order = self.client_binance.create_order(
        symbol=self.operation_code,
    ...<2 lines>...
        quantity=str(quantity)
    )
  File "C:\Users\paulo\python\Robo crypto\.venv\Lib\site-packages\binance\client.py", line 1333, in create_order
    return self._post("order", True, data=params)
           ~~~~~~~~~~^^^^^^^^^^^^^^^^^^^^^^^^^^^^
  File "C:\Users\paulo\python\Robo crypto\.venv\Lib\site-packages\binance\client.py", line 181, in _post
    return self._request_api("post", path, signed, version, **kwargs)
           ~~~~~~~~~~~~~~~~~^^^^^^^^^^^^^^^^^^^^^^^^^^^^^^^^^^^^^^^^^
  File "C:\Users\paulo\python\Robo crypto\.venv\Lib\site-packages\binance\client.py", line 113, in _request_api
    return self._request(method, uri, signed, **kwargs)
           ~~~~~~~~~~~~~^^^^^^^^^^^^^^^^^^^^^^^^^^^^^^^
  File "C:\Users\paulo\python\Robo crypto\.venv\Lib\site-packages\binance\client.py", line 89, in _request
    return self._handle_response(self.response)
           ~~~~~~~~~~~~~~~~~~~~~^^^^^^^^^^^^^^^
  File "C:\Users\paulo\python\Robo crypto\.venv\Lib\site-packages\binance\client.py", line 98, in _handle_response
    raise BinanceAPIException(response, response.status_code, response.text)
binance.exceptions.BinanceAPIException: APIError(code=-1013): Filter failure: NOTIONAL
2025-01-11 10:52:32,509 - ERROR - Erro da Binance API: APIError(code=-1013): Filter failure: NOTIONAL
Traceback (most recent call last):
  File "c:\Users\paulo\python\Robo crypto\src\BinanceTrader2.py", line 162, in execute_trade
    order = self.client_binance.create_order(
        symbol=self.operation_code,
    ...<2 lines>...
        quantity=str(quantity)
    )
  File "C:\Users\paulo\python\Robo crypto\.venv\Lib\site-packages\binance\client.py", line 1333, in create_order
    return self._post("order", True, data=params)
           ~~~~~~~~~~^^^^^^^^^^^^^^^^^^^^^^^^^^^^
  File "C:\Users\paulo\python\Robo crypto\.venv\Lib\site-packages\binance\client.py", line 181, in _post
    return self._request_api("post", path, signed, version, **kwargs)
           ~~~~~~~~~~~~~~~~~^^^^^^^^^^^^^^^^^^^^^^^^^^^^^^^^^^^^^^^^^
  File "C:\Users\paulo\python\Robo crypto\.venv\Lib\site-packages\binance\client.py", line 113, in _request_api
    return self._request(method, uri, signed, **kwargs)
           ~~~~~~~~~~~~~^^^^^^^^^^^^^^^^^^^^^^^^^^^^^^^
  File "C:\Users\paulo\python\Robo crypto\.venv\Lib\site-packages\binance\client.py", line 89, in _request
    return self._handle_response(self.response)
           ~~~~~~~~~~~~~~~~~~~~~^^^^^^^^^^^^^^^
  File "C:\Users\paulo\python\Robo crypto\.venv\Lib\site-packages\binance\client.py", line 98, in _handle_response
    raise BinanceAPIException(response, response.status_code, response.text)
binance.exceptions.BinanceAPIException: APIError(code=-1013): Filter failure: NOTIONAL
2025-01-11 10:53:34,471 - ERROR - Erro da Binance API: APIError(code=-1013): Filter failure: NOTIONAL
Traceback (most recent call last):
  File "c:\Users\paulo\python\Robo crypto\src\BinanceTrader2.py", line 162, in execute_trade
    order = self.client_binance.create_order(
        symbol=self.operation_code,
    ...<2 lines>...
        quantity=str(quantity)
    )
  File "C:\Users\paulo\python\Robo crypto\.venv\Lib\site-packages\binance\client.py", line 1333, in create_order
    return self._post("order", True, data=params)
           ~~~~~~~~~~^^^^^^^^^^^^^^^^^^^^^^^^^^^^
  File "C:\Users\paulo\python\Robo crypto\.venv\Lib\site-packages\binance\client.py", line 181, in _post
    return self._request_api("post", path, signed, version, **kwargs)
           ~~~~~~~~~~~~~~~~~^^^^^^^^^^^^^^^^^^^^^^^^^^^^^^^^^^^^^^^^^
  File "C:\Users\paulo\python\Robo crypto\.venv\Lib\site-packages\binance\client.py", line 113, in _request_api
    return self._request(method, uri, signed, **kwargs)
           ~~~~~~~~~~~~~^^^^^^^^^^^^^^^^^^^^^^^^^^^^^^^
  File "C:\Users\paulo\python\Robo crypto\.venv\Lib\site-packages\binance\client.py", line 89, in _request
    return self._handle_response(self.response)
           ~~~~~~~~~~~~~~~~~~~~~^^^^^^^^^^^^^^^
  File "C:\Users\paulo\python\Robo crypto\.venv\Lib\site-packages\binance\client.py", line 98, in _handle_response
    raise BinanceAPIException(response, response.status_code, response.text)
binance.exceptions.BinanceAPIException: APIError(code=-1013): Filter failure: NOTIONAL
2025-01-11 10:54:36,622 - ERROR - Erro da Binance API: APIError(code=-1013): Filter failure: NOTIONAL
Traceback (most recent call last):
  File "c:\Users\paulo\python\Robo crypto\src\BinanceTrader2.py", line 162, in execute_trade
    order = self.client_binance.create_order(
        symbol=self.operation_code,
    ...<2 lines>...
        quantity=str(quantity)
    )
  File "C:\Users\paulo\python\Robo crypto\.venv\Lib\site-packages\binance\client.py", line 1333, in create_order
    return self._post("order", True, data=params)
           ~~~~~~~~~~^^^^^^^^^^^^^^^^^^^^^^^^^^^^
  File "C:\Users\paulo\python\Robo crypto\.venv\Lib\site-packages\binance\client.py", line 181, in _post
    return self._request_api("post", path, signed, version, **kwargs)
           ~~~~~~~~~~~~~~~~~^^^^^^^^^^^^^^^^^^^^^^^^^^^^^^^^^^^^^^^^^
  File "C:\Users\paulo\python\Robo crypto\.venv\Lib\site-packages\binance\client.py", line 113, in _request_api
    return self._request(method, uri, signed, **kwargs)
           ~~~~~~~~~~~~~^^^^^^^^^^^^^^^^^^^^^^^^^^^^^^^
  File "C:\Users\paulo\python\Robo crypto\.venv\Lib\site-packages\binance\client.py", line 89, in _request
    return self._handle_response(self.response)
           ~~~~~~~~~~~~~~~~~~~~~^^^^^^^^^^^^^^^
  File "C:\Users\paulo\python\Robo crypto\.venv\Lib\site-packages\binance\client.py", line 98, in _handle_response
    raise BinanceAPIException(response, response.status_code, response.text)
binance.exceptions.BinanceAPIException: APIError(code=-1013): Filter failure: NOTIONAL
2025-01-11 10:55:38,778 - ERROR - Erro da Binance API: APIError(code=-1013): Filter failure: NOTIONAL
Traceback (most recent call last):
  File "c:\Users\paulo\python\Robo crypto\src\BinanceTrader2.py", line 162, in execute_trade
    order = self.client_binance.create_order(
        symbol=self.operation_code,
    ...<2 lines>...
        quantity=str(quantity)
    )
  File "C:\Users\paulo\python\Robo crypto\.venv\Lib\site-packages\binance\client.py", line 1333, in create_order
    return self._post("order", True, data=params)
           ~~~~~~~~~~^^^^^^^^^^^^^^^^^^^^^^^^^^^^
  File "C:\Users\paulo\python\Robo crypto\.venv\Lib\site-packages\binance\client.py", line 181, in _post
    return self._request_api("post", path, signed, version, **kwargs)
           ~~~~~~~~~~~~~~~~~^^^^^^^^^^^^^^^^^^^^^^^^^^^^^^^^^^^^^^^^^
  File "C:\Users\paulo\python\Robo crypto\.venv\Lib\site-packages\binance\client.py", line 113, in _request_api
    return self._request(method, uri, signed, **kwargs)
           ~~~~~~~~~~~~~^^^^^^^^^^^^^^^^^^^^^^^^^^^^^^^
  File "C:\Users\paulo\python\Robo crypto\.venv\Lib\site-packages\binance\client.py", line 89, in _request
    return self._handle_response(self.response)
           ~~~~~~~~~~~~~~~~~~~~~^^^^^^^^^^^^^^^
  File "C:\Users\paulo\python\Robo crypto\.venv\Lib\site-packages\binance\client.py", line 98, in _handle_response
    raise BinanceAPIException(response, response.status_code, response.text)
binance.exceptions.BinanceAPIException: APIError(code=-1013): Filter failure: NOTIONAL
2025-01-11 10:56:41,047 - ERROR - Erro da Binance API: APIError(code=-1013): Filter failure: NOTIONAL
Traceback (most recent call last):
  File "c:\Users\paulo\python\Robo crypto\src\BinanceTrader2.py", line 162, in execute_trade
    order = self.client_binance.create_order(
        symbol=self.operation_code,
    ...<2 lines>...
        quantity=str(quantity)
    )
  File "C:\Users\paulo\python\Robo crypto\.venv\Lib\site-packages\binance\client.py", line 1333, in create_order
    return self._post("order", True, data=params)
           ~~~~~~~~~~^^^^^^^^^^^^^^^^^^^^^^^^^^^^
  File "C:\Users\paulo\python\Robo crypto\.venv\Lib\site-packages\binance\client.py", line 181, in _post
    return self._request_api("post", path, signed, version, **kwargs)
           ~~~~~~~~~~~~~~~~~^^^^^^^^^^^^^^^^^^^^^^^^^^^^^^^^^^^^^^^^^
  File "C:\Users\paulo\python\Robo crypto\.venv\Lib\site-packages\binance\client.py", line 113, in _request_api
    return self._request(method, uri, signed, **kwargs)
           ~~~~~~~~~~~~~^^^^^^^^^^^^^^^^^^^^^^^^^^^^^^^
  File "C:\Users\paulo\python\Robo crypto\.venv\Lib\site-packages\binance\client.py", line 89, in _request
    return self._handle_response(self.response)
           ~~~~~~~~~~~~~~~~~~~~~^^^^^^^^^^^^^^^
  File "C:\Users\paulo\python\Robo crypto\.venv\Lib\site-packages\binance\client.py", line 98, in _handle_response
    raise BinanceAPIException(response, response.status_code, response.text)
binance.exceptions.BinanceAPIException: APIError(code=-1013): Filter failure: NOTIONAL
2025-01-11 10:57:42,788 - ERROR - Erro da Binance API: APIError(code=-1013): Filter failure: NOTIONAL
Traceback (most recent call last):
  File "c:\Users\paulo\python\Robo crypto\src\BinanceTrader2.py", line 162, in execute_trade
    order = self.client_binance.create_order(
        symbol=self.operation_code,
    ...<2 lines>...
        quantity=str(quantity)
    )
  File "C:\Users\paulo\python\Robo crypto\.venv\Lib\site-packages\binance\client.py", line 1333, in create_order
    return self._post("order", True, data=params)
           ~~~~~~~~~~^^^^^^^^^^^^^^^^^^^^^^^^^^^^
  File "C:\Users\paulo\python\Robo crypto\.venv\Lib\site-packages\binance\client.py", line 181, in _post
    return self._request_api("post", path, signed, version, **kwargs)
           ~~~~~~~~~~~~~~~~~^^^^^^^^^^^^^^^^^^^^^^^^^^^^^^^^^^^^^^^^^
  File "C:\Users\paulo\python\Robo crypto\.venv\Lib\site-packages\binance\client.py", line 113, in _request_api
    return self._request(method, uri, signed, **kwargs)
           ~~~~~~~~~~~~~^^^^^^^^^^^^^^^^^^^^^^^^^^^^^^^
  File "C:\Users\paulo\python\Robo crypto\.venv\Lib\site-packages\binance\client.py", line 89, in _request
    return self._handle_response(self.response)
           ~~~~~~~~~~~~~~~~~~~~~^^^^^^^^^^^^^^^
  File "C:\Users\paulo\python\Robo crypto\.venv\Lib\site-packages\binance\client.py", line 98, in _handle_response
    raise BinanceAPIException(response, response.status_code, response.text)
binance.exceptions.BinanceAPIException: APIError(code=-1013): Filter failure: NOTIONAL
2025-01-11 10:58:44,945 - ERROR - Erro da Binance API: APIError(code=-1013): Filter failure: NOTIONAL
Traceback (most recent call last):
  File "c:\Users\paulo\python\Robo crypto\src\BinanceTrader2.py", line 162, in execute_trade
    order = self.client_binance.create_order(
        symbol=self.operation_code,
    ...<2 lines>...
        quantity=str(quantity)
    )
  File "C:\Users\paulo\python\Robo crypto\.venv\Lib\site-packages\binance\client.py", line 1333, in create_order
    return self._post("order", True, data=params)
           ~~~~~~~~~~^^^^^^^^^^^^^^^^^^^^^^^^^^^^
  File "C:\Users\paulo\python\Robo crypto\.venv\Lib\site-packages\binance\client.py", line 181, in _post
    return self._request_api("post", path, signed, version, **kwargs)
           ~~~~~~~~~~~~~~~~~^^^^^^^^^^^^^^^^^^^^^^^^^^^^^^^^^^^^^^^^^
  File "C:\Users\paulo\python\Robo crypto\.venv\Lib\site-packages\binance\client.py", line 113, in _request_api
    return self._request(method, uri, signed, **kwargs)
           ~~~~~~~~~~~~~^^^^^^^^^^^^^^^^^^^^^^^^^^^^^^^
  File "C:\Users\paulo\python\Robo crypto\.venv\Lib\site-packages\binance\client.py", line 89, in _request
    return self._handle_response(self.response)
           ~~~~~~~~~~~~~~~~~~~~~^^^^^^^^^^^^^^^
  File "C:\Users\paulo\python\Robo crypto\.venv\Lib\site-packages\binance\client.py", line 98, in _handle_response
    raise BinanceAPIException(response, response.status_code, response.text)
binance.exceptions.BinanceAPIException: APIError(code=-1013): Filter failure: NOTIONAL
2025-01-11 10:59:47,411 - ERROR - Erro da Binance API: APIError(code=-1013): Filter failure: NOTIONAL
Traceback (most recent call last):
  File "c:\Users\paulo\python\Robo crypto\src\BinanceTrader2.py", line 162, in execute_trade
    order = self.client_binance.create_order(
        symbol=self.operation_code,
    ...<2 lines>...
        quantity=str(quantity)
    )
  File "C:\Users\paulo\python\Robo crypto\.venv\Lib\site-packages\binance\client.py", line 1333, in create_order
    return self._post("order", True, data=params)
           ~~~~~~~~~~^^^^^^^^^^^^^^^^^^^^^^^^^^^^
  File "C:\Users\paulo\python\Robo crypto\.venv\Lib\site-packages\binance\client.py", line 181, in _post
    return self._request_api("post", path, signed, version, **kwargs)
           ~~~~~~~~~~~~~~~~~^^^^^^^^^^^^^^^^^^^^^^^^^^^^^^^^^^^^^^^^^
  File "C:\Users\paulo\python\Robo crypto\.venv\Lib\site-packages\binance\client.py", line 113, in _request_api
    return self._request(method, uri, signed, **kwargs)
           ~~~~~~~~~~~~~^^^^^^^^^^^^^^^^^^^^^^^^^^^^^^^
  File "C:\Users\paulo\python\Robo crypto\.venv\Lib\site-packages\binance\client.py", line 89, in _request
    return self._handle_response(self.response)
           ~~~~~~~~~~~~~~~~~~~~~^^^^^^^^^^^^^^^
  File "C:\Users\paulo\python\Robo crypto\.venv\Lib\site-packages\binance\client.py", line 98, in _handle_response
    raise BinanceAPIException(response, response.status_code, response.text)
binance.exceptions.BinanceAPIException: APIError(code=-1013): Filter failure: NOTIONAL
2025-01-11 11:00:49,370 - ERROR - Erro da Binance API: APIError(code=-1013): Filter failure: NOTIONAL
Traceback (most recent call last):
  File "c:\Users\paulo\python\Robo crypto\src\BinanceTrader2.py", line 162, in execute_trade
    order = self.client_binance.create_order(
        symbol=self.operation_code,
    ...<2 lines>...
        quantity=str(quantity)
    )
  File "C:\Users\paulo\python\Robo crypto\.venv\Lib\site-packages\binance\client.py", line 1333, in create_order
    return self._post("order", True, data=params)
           ~~~~~~~~~~^^^^^^^^^^^^^^^^^^^^^^^^^^^^
  File "C:\Users\paulo\python\Robo crypto\.venv\Lib\site-packages\binance\client.py", line 181, in _post
    return self._request_api("post", path, signed, version, **kwargs)
           ~~~~~~~~~~~~~~~~~^^^^^^^^^^^^^^^^^^^^^^^^^^^^^^^^^^^^^^^^^
  File "C:\Users\paulo\python\Robo crypto\.venv\Lib\site-packages\binance\client.py", line 113, in _request_api
    return self._request(method, uri, signed, **kwargs)
           ~~~~~~~~~~~~~^^^^^^^^^^^^^^^^^^^^^^^^^^^^^^^
  File "C:\Users\paulo\python\Robo crypto\.venv\Lib\site-packages\binance\client.py", line 89, in _request
    return self._handle_response(self.response)
           ~~~~~~~~~~~~~~~~~~~~~^^^^^^^^^^^^^^^
  File "C:\Users\paulo\python\Robo crypto\.venv\Lib\site-packages\binance\client.py", line 98, in _handle_response
    raise BinanceAPIException(response, response.status_code, response.text)
binance.exceptions.BinanceAPIException: APIError(code=-1013): Filter failure: NOTIONAL
2025-01-11 11:01:51,419 - ERROR - Erro da Binance API: APIError(code=-1013): Filter failure: NOTIONAL
Traceback (most recent call last):
  File "c:\Users\paulo\python\Robo crypto\src\BinanceTrader2.py", line 162, in execute_trade
    order = self.client_binance.create_order(
        symbol=self.operation_code,
    ...<2 lines>...
        quantity=str(quantity)
    )
  File "C:\Users\paulo\python\Robo crypto\.venv\Lib\site-packages\binance\client.py", line 1333, in create_order
    return self._post("order", True, data=params)
           ~~~~~~~~~~^^^^^^^^^^^^^^^^^^^^^^^^^^^^
  File "C:\Users\paulo\python\Robo crypto\.venv\Lib\site-packages\binance\client.py", line 181, in _post
    return self._request_api("post", path, signed, version, **kwargs)
           ~~~~~~~~~~~~~~~~~^^^^^^^^^^^^^^^^^^^^^^^^^^^^^^^^^^^^^^^^^
  File "C:\Users\paulo\python\Robo crypto\.venv\Lib\site-packages\binance\client.py", line 113, in _request_api
    return self._request(method, uri, signed, **kwargs)
           ~~~~~~~~~~~~~^^^^^^^^^^^^^^^^^^^^^^^^^^^^^^^
  File "C:\Users\paulo\python\Robo crypto\.venv\Lib\site-packages\binance\client.py", line 89, in _request
    return self._handle_response(self.response)
           ~~~~~~~~~~~~~~~~~~~~~^^^^^^^^^^^^^^^
  File "C:\Users\paulo\python\Robo crypto\.venv\Lib\site-packages\binance\client.py", line 98, in _handle_response
    raise BinanceAPIException(response, response.status_code, response.text)
binance.exceptions.BinanceAPIException: APIError(code=-1013): Filter failure: NOTIONAL
2025-01-11 11:02:53,167 - ERROR - Erro da Binance API: APIError(code=-1013): Filter failure: NOTIONAL
Traceback (most recent call last):
  File "c:\Users\paulo\python\Robo crypto\src\BinanceTrader2.py", line 162, in execute_trade
    order = self.client_binance.create_order(
        symbol=self.operation_code,
    ...<2 lines>...
        quantity=str(quantity)
    )
  File "C:\Users\paulo\python\Robo crypto\.venv\Lib\site-packages\binance\client.py", line 1333, in create_order
    return self._post("order", True, data=params)
           ~~~~~~~~~~^^^^^^^^^^^^^^^^^^^^^^^^^^^^
  File "C:\Users\paulo\python\Robo crypto\.venv\Lib\site-packages\binance\client.py", line 181, in _post
    return self._request_api("post", path, signed, version, **kwargs)
           ~~~~~~~~~~~~~~~~~^^^^^^^^^^^^^^^^^^^^^^^^^^^^^^^^^^^^^^^^^
  File "C:\Users\paulo\python\Robo crypto\.venv\Lib\site-packages\binance\client.py", line 113, in _request_api
    return self._request(method, uri, signed, **kwargs)
           ~~~~~~~~~~~~~^^^^^^^^^^^^^^^^^^^^^^^^^^^^^^^
  File "C:\Users\paulo\python\Robo crypto\.venv\Lib\site-packages\binance\client.py", line 89, in _request
    return self._handle_response(self.response)
           ~~~~~~~~~~~~~~~~~~~~~^^^^^^^^^^^^^^^
  File "C:\Users\paulo\python\Robo crypto\.venv\Lib\site-packages\binance\client.py", line 98, in _handle_response
    raise BinanceAPIException(response, response.status_code, response.text)
binance.exceptions.BinanceAPIException: APIError(code=-1013): Filter failure: NOTIONAL
2025-01-11 11:03:55,735 - ERROR - Erro da Binance API: APIError(code=-1013): Filter failure: NOTIONAL
Traceback (most recent call last):
  File "c:\Users\paulo\python\Robo crypto\src\BinanceTrader2.py", line 162, in execute_trade
    order = self.client_binance.create_order(
        symbol=self.operation_code,
    ...<2 lines>...
        quantity=str(quantity)
    )
  File "C:\Users\paulo\python\Robo crypto\.venv\Lib\site-packages\binance\client.py", line 1333, in create_order
    return self._post("order", True, data=params)
           ~~~~~~~~~~^^^^^^^^^^^^^^^^^^^^^^^^^^^^
  File "C:\Users\paulo\python\Robo crypto\.venv\Lib\site-packages\binance\client.py", line 181, in _post
    return self._request_api("post", path, signed, version, **kwargs)
           ~~~~~~~~~~~~~~~~~^^^^^^^^^^^^^^^^^^^^^^^^^^^^^^^^^^^^^^^^^
  File "C:\Users\paulo\python\Robo crypto\.venv\Lib\site-packages\binance\client.py", line 113, in _request_api
    return self._request(method, uri, signed, **kwargs)
           ~~~~~~~~~~~~~^^^^^^^^^^^^^^^^^^^^^^^^^^^^^^^
  File "C:\Users\paulo\python\Robo crypto\.venv\Lib\site-packages\binance\client.py", line 89, in _request
    return self._handle_response(self.response)
           ~~~~~~~~~~~~~~~~~~~~~^^^^^^^^^^^^^^^
  File "C:\Users\paulo\python\Robo crypto\.venv\Lib\site-packages\binance\client.py", line 98, in _handle_response
    raise BinanceAPIException(response, response.status_code, response.text)
binance.exceptions.BinanceAPIException: APIError(code=-1013): Filter failure: NOTIONAL
2025-01-11 11:04:57,789 - ERROR - Erro da Binance API: APIError(code=-1013): Filter failure: NOTIONAL
Traceback (most recent call last):
  File "c:\Users\paulo\python\Robo crypto\src\BinanceTrader2.py", line 162, in execute_trade
    order = self.client_binance.create_order(
        symbol=self.operation_code,
    ...<2 lines>...
        quantity=str(quantity)
    )
  File "C:\Users\paulo\python\Robo crypto\.venv\Lib\site-packages\binance\client.py", line 1333, in create_order
    return self._post("order", True, data=params)
           ~~~~~~~~~~^^^^^^^^^^^^^^^^^^^^^^^^^^^^
  File "C:\Users\paulo\python\Robo crypto\.venv\Lib\site-packages\binance\client.py", line 181, in _post
    return self._request_api("post", path, signed, version, **kwargs)
           ~~~~~~~~~~~~~~~~~^^^^^^^^^^^^^^^^^^^^^^^^^^^^^^^^^^^^^^^^^
  File "C:\Users\paulo\python\Robo crypto\.venv\Lib\site-packages\binance\client.py", line 113, in _request_api
    return self._request(method, uri, signed, **kwargs)
           ~~~~~~~~~~~~~^^^^^^^^^^^^^^^^^^^^^^^^^^^^^^^
  File "C:\Users\paulo\python\Robo crypto\.venv\Lib\site-packages\binance\client.py", line 89, in _request
    return self._handle_response(self.response)
           ~~~~~~~~~~~~~~~~~~~~~^^^^^^^^^^^^^^^
  File "C:\Users\paulo\python\Robo crypto\.venv\Lib\site-packages\binance\client.py", line 98, in _handle_response
    raise BinanceAPIException(response, response.status_code, response.text)
binance.exceptions.BinanceAPIException: APIError(code=-1013): Filter failure: NOTIONAL
2025-01-11 11:05:59,846 - ERROR - Erro da Binance API: APIError(code=-1013): Filter failure: NOTIONAL
Traceback (most recent call last):
  File "c:\Users\paulo\python\Robo crypto\src\BinanceTrader2.py", line 162, in execute_trade
    order = self.client_binance.create_order(
        symbol=self.operation_code,
    ...<2 lines>...
        quantity=str(quantity)
    )
  File "C:\Users\paulo\python\Robo crypto\.venv\Lib\site-packages\binance\client.py", line 1333, in create_order
    return self._post("order", True, data=params)
           ~~~~~~~~~~^^^^^^^^^^^^^^^^^^^^^^^^^^^^
  File "C:\Users\paulo\python\Robo crypto\.venv\Lib\site-packages\binance\client.py", line 181, in _post
    return self._request_api("post", path, signed, version, **kwargs)
           ~~~~~~~~~~~~~~~~~^^^^^^^^^^^^^^^^^^^^^^^^^^^^^^^^^^^^^^^^^
  File "C:\Users\paulo\python\Robo crypto\.venv\Lib\site-packages\binance\client.py", line 113, in _request_api
    return self._request(method, uri, signed, **kwargs)
           ~~~~~~~~~~~~~^^^^^^^^^^^^^^^^^^^^^^^^^^^^^^^
  File "C:\Users\paulo\python\Robo crypto\.venv\Lib\site-packages\binance\client.py", line 89, in _request
    return self._handle_response(self.response)
           ~~~~~~~~~~~~~~~~~~~~~^^^^^^^^^^^^^^^
  File "C:\Users\paulo\python\Robo crypto\.venv\Lib\site-packages\binance\client.py", line 98, in _handle_response
    raise BinanceAPIException(response, response.status_code, response.text)
binance.exceptions.BinanceAPIException: APIError(code=-1013): Filter failure: NOTIONAL
2025-01-11 11:07:09,688 - ERROR - Erro da Binance API: APIError(code=-1013): Filter failure: NOTIONAL
Traceback (most recent call last):
  File "c:\Users\paulo\python\Robo crypto\src\BinanceTrader2.py", line 162, in execute_trade
    order = self.client_binance.create_order(
        symbol=self.operation_code,
    ...<2 lines>...
        quantity=str(quantity)
    )
  File "C:\Users\paulo\python\Robo crypto\.venv\Lib\site-packages\binance\client.py", line 1333, in create_order
    return self._post("order", True, data=params)
           ~~~~~~~~~~^^^^^^^^^^^^^^^^^^^^^^^^^^^^
  File "C:\Users\paulo\python\Robo crypto\.venv\Lib\site-packages\binance\client.py", line 181, in _post
    return self._request_api("post", path, signed, version, **kwargs)
           ~~~~~~~~~~~~~~~~~^^^^^^^^^^^^^^^^^^^^^^^^^^^^^^^^^^^^^^^^^
  File "C:\Users\paulo\python\Robo crypto\.venv\Lib\site-packages\binance\client.py", line 113, in _request_api
    return self._request(method, uri, signed, **kwargs)
           ~~~~~~~~~~~~~^^^^^^^^^^^^^^^^^^^^^^^^^^^^^^^
  File "C:\Users\paulo\python\Robo crypto\.venv\Lib\site-packages\binance\client.py", line 89, in _request
    return self._handle_response(self.response)
           ~~~~~~~~~~~~~~~~~~~~~^^^^^^^^^^^^^^^
  File "C:\Users\paulo\python\Robo crypto\.venv\Lib\site-packages\binance\client.py", line 98, in _handle_response
    raise BinanceAPIException(response, response.status_code, response.text)
binance.exceptions.BinanceAPIException: APIError(code=-1013): Filter failure: NOTIONAL
2025-01-11 11:08:52,542 - ERROR - Erro da Binance API: APIError(code=-1013): Filter failure: NOTIONAL
Traceback (most recent call last):
  File "c:\Users\paulo\python\Robo crypto\src\BinanceTrader2.py", line 162, in execute_trade
    order = self.client_binance.create_order(
        symbol=self.operation_code,
    ...<2 lines>...
        quantity=str(quantity)
    )
  File "C:\Users\paulo\python\Robo crypto\.venv\Lib\site-packages\binance\client.py", line 1333, in create_order
    return self._post("order", True, data=params)
           ~~~~~~~~~~^^^^^^^^^^^^^^^^^^^^^^^^^^^^
  File "C:\Users\paulo\python\Robo crypto\.venv\Lib\site-packages\binance\client.py", line 181, in _post
    return self._request_api("post", path, signed, version, **kwargs)
           ~~~~~~~~~~~~~~~~~^^^^^^^^^^^^^^^^^^^^^^^^^^^^^^^^^^^^^^^^^
  File "C:\Users\paulo\python\Robo crypto\.venv\Lib\site-packages\binance\client.py", line 113, in _request_api
    return self._request(method, uri, signed, **kwargs)
           ~~~~~~~~~~~~~^^^^^^^^^^^^^^^^^^^^^^^^^^^^^^^
  File "C:\Users\paulo\python\Robo crypto\.venv\Lib\site-packages\binance\client.py", line 89, in _request
    return self._handle_response(self.response)
           ~~~~~~~~~~~~~~~~~~~~~^^^^^^^^^^^^^^^
  File "C:\Users\paulo\python\Robo crypto\.venv\Lib\site-packages\binance\client.py", line 98, in _handle_response
    raise BinanceAPIException(response, response.status_code, response.text)
binance.exceptions.BinanceAPIException: APIError(code=-1013): Filter failure: NOTIONAL
